Workbook

Sheet Billet and Gauge
B2: RATES ARE IN PER METRIC TON | F2: Daily Input
F3: Twice Mthly Input
B4: Date | C4: 46120 | F4: Auto Populate
F5: No Inputs
B6: Zinc (HZL List) | C6: 409500
B8: Billets | C8: Ryp_Coml (L) | D8: Ryp_Coml (H) | E8: Ryp_Test (L) | F8: Ryp_Test (H) | G8: Ngp_Test (H) | H8: SAIL_Dgp | I8: SAIL_Kol | J8: SAIL_Ryp | K8: SAIL_Ngp | L8: SAIL_Rour | M8: JSPL_Rgh
C9: 38511 | D9: 44511 | E9: =C9+4000 -> 42511 | F9: =D9+4000 -> 48511 | G9: =E9+1500 -> 44011 | H9: 44500 | I9: =H9+1000 -> 45500 | J9: =H9+2250 -> 46750 | K9: =H9+2750 -> 47250 | L9: =H9+1450 -> 45950 | M9: 50000
B11: HR Plates - 16, 20 mm | C11: Raipur_IS2062 | D11: Rourkela_IS2062 | E11: Raigarh_IS2062
C12: 57000 | D12: 57000 | E12: 59000
B14: HR Coil - 2.5 to 8 mm | C14: Kolkatta_IS2062 | D14: Raipur_IS2062 | E14: NCR_IS2062 | H14: RM Category
C15: 57000 | D15: 56075 | E15: 57000 | H15: PG /NTPC | I15: MS
H16: MAIN /BSEN | I16: MS
B17: Wire Rods - 16/22 mm | C17: Ludhiana_Coml | D17: RINL/JSW (Pb) | E17: RINL/JSW (Lkw) | H17: NPG | I17: MS
C18: 54000 | D18: 61000 | E18: 59500 | H18: CORE | I18: MS
H19: PG /NTPC | I19: HT
B20: Rounds - 28 to 56 mm | C20: Delhi (Coml) | D20: RINL/JSW (Pb) | E20: RINL/JSW (Ngp) | F20: RINL/JSW (Lkw) | G20: RINL/JSW (Jpr) | H20: MAIN /BSEN | I20: HT
C21: 52500 | D21: 59000 | E21: 55500 | F21: 58000 | G21: 58500 | H21: NPG | I21: HT
H22: CORE | I22: HT
B23: Gauge Sheet
B24: Updated | C24: 03.04.26
B25: MS Angle | C25: Sections | D25: Gauge Diff
B26: Base Angles | C26: L-50X6, 65X6, 75X6 | D26: 6500
C27: L-50X5/8, 65X5/8, 75X5/8 | D27: 6800
B28: TLT Angles | C28: L-40x4/5/6, L-45x4/5/6, L-50x4, L-55x4/5, L-60x4/5, L-65X4, L-70x5/6, L-75x10, L-80x6/8 | D28: 7700
B29: Unequal Angles | C29: UL-45x30x4/ 45x30x5 | D29: 9000
B30: Medium Angles (BALAJEE) | C30: L-90x6/8/10 | D30: 7500
C31: L-100X6/8/10/12 | D31: 7500
C32: L-110X8/10/12 | D32: 8200
B34: Medium Angles (MAHAMAYA) | C34: L-90x6/8/10 | D34: 500
C35: L-100X6/8/10/12 | D35: 500
C36: L-110X8/10/12 | D36: 1000
B37: Heavy Angles | C37: L-130X10/12 | D37: 2500
C38: L-150X10/12/16/20 | D38: 4000
B39: Super Heavy Angles | C39: L-200X12/16/20 | D39: 5500
C40: L-200X25 | D40: 6500
B42: Light - Medium (SREL) | C42: L-45 to L-130 | D42: 9500
B43: Heavy (SREL) | C43: L-150 | D43: 10000
B44: Super Heavy (SREL) | C44: L-200 | D44: 10500
B45: Ultra Heavy (SREL) | C45: L-250 | D45: 14000
B47: Light (JSPL) | C47: L-75 to L-90 | D47: 9000
...

Sheet RM Price List
B1: RATES ARE IN PER METRIC TON
B3: Angles | C3: MS | D3: ='Billet and Gauge'!C130 -> 0
C4: HT (Gauge Diff.) | D4: 3500
C5: Base Price: | D5: ='Billet and Gauge'!C9 -> 38511 | E5: ='Billet and Gauge'!C9 -> 38511 | F5: ='Billet and Gauge'!D9 -> 44511 | G5: ='Billet and Gauge'!D9 -> 44511 | H5: ='Billet and Gauge'!K9 -> 47250 | I5: ='Billet and Gauge'!J9 -> 46750 | J5: ='Billet and Gauge'!J9 -> 46750 | K5: ='Billet and Gauge'!J9 -> 46750 | L5: ='Billet and Gauge'!F9 -> 48511 | M5: ='Billet and Gauge'!E9 -> 42511 | N5: ='Billet and Gauge'!G9 -> 44011 | O5: ='Billet and Gauge'!E9 -> 42511 | P5: ='Billet and Gauge'!M9 -> 50000
C6: Load+Trspt+Brok | D6: =385+250+85 -> 720 | E6: =385+250+85 -> 720 | F6: =385+250+85 -> 720 | G6: =385+250+85 -> 720 | H6: 1250 | I6: =385+250+85 -> 720 | J6: =385+250+85 -> 720 | K6: 1250 | L6: =385+250+85 -> 720 | M6: =385+250+85 -> 720 | N6: 1250 | O6: =385+250+85 -> 720 | P6: 1100
C7: Make: | D7: (NPG) | E7: (NPG) | F7: (NPG) | G7: (NPG) | H7: (PG) | I7: (PG) | J7: (PG) | K7: (PG) | L7: (TESTED) | M7: (TESTED) | N7: (MAIN/BSEN) | O7: (MAIN) | P7: (PG/NTPC)
B8: Sections | C8: Supplier: | D8: BALAJEE | E8: JAI AMBE | F8: NSPL | G8: VANDANA | H8: SREL | I8: KIPL | J8: SBAL | K8: NSPL | L8: NSPL | M8: MADHUR | N8: SREL | O8: BALAJEE | P8: JSPL
B9: 50/65/75 x 6/8 mm | C9: Light | D9: =D5+D6+'Billet and Gauge'!D26 -> 45731 | E9: =E5+E6+'Billet and Gauge'!D26 -> 45731 | F9: - | G9: - | H9: =H5+H6+'Billet and Gauge'!D42 -> 58000 | I9: =I5+I6+'Billet and Gauge'!D42 -> 56970 | J9: - | K9: =K5+K6+'Billet and Gauge'!D42 -> 57500 | L9: - | M9: =M5+M6+'Billet and Gauge'!D26 -> 49731 | N9: =N5+N6+'Billet and Gauge'!D42 -> 54761 | O9: =O5+O6+'Billet and Gauge'!D26 -> 49731 | P9: -
B10: 50/65/75 x 5 mm | C10: Light | D10: =D5+D6+'Billet and Gauge'!D27 -> 46031 | E10: =E5+E6+'Billet and Gauge'!D27 -> 46031 | F10: - | G10: - | H10: =H5+H6+'Billet and Gauge'!D42 -> 58000 | I10: =I5+I6+'Billet and Gauge'!D42 -> 56970 | J10: - | K10: =K5+K6+'Billet and Gauge'!D42 -> 57500 | L10: - | M10: =M5+M6+'Billet and Gauge'!D27 -> 50031 | N10: =N5+N6+'Billet and Gauge'!D42 -> 54761 | O10: =O5+O6+'Billet and Gauge'!D27 -> 50031 | P10: -
B11: TLT 45 - 80 mm | C11: Light | D11: =D5+D6+'Billet and Gauge'!D28 -> 46931 | E11: =E5+E6+'Billet and Gauge'!D28 -> 46931 | F11: - | G11: - | H11: =H5+H6+'Billet and Gauge'!D42 -> 58000 | I11: =I5+I6+'Billet and Gauge'!D42 -> 56970 | J11: =J5+J6+'Billet and Gauge'!D42 -> 56970 | K11: =K5+K6+'Billet and Gauge'!D42 -> 57500 | L11: - | M11: =M5+M6+'Billet and Gauge'!D28 -> 50931 | N11: =N5+N6+'Billet and Gauge'!D42 -> 54761 | O11: =O5+O6+'Billet and Gauge'!D28 -> 50931 | P11: -
B12: TLT 90 - 110 mm | C12: Medium | D12: =D5+D6+'Billet and Gauge'!D30 -> 46731 | E12: =E5+E6+'Billet and Gauge'!D30 -> 46731 | F12: =F5+F6+'Billet and Gauge'!D36 -> 46231 | G12: =G5+G6+'Billet and Gauge'!D36 -> 46231 | H12: =H5+H6+'Billet and Gauge'!D42 -> 58000 | I12: =I5+I6+'Billet and Gauge'!D42 -> 56970 | J12: =J5+J6+'Billet and Gauge'!D42 -> 56970 | K12: =K5+K6+'Billet and Gauge'!D45 -> 62000 | L12: =L5+L6+'Billet and Gauge'!D36 -> 50231 | M12: =M5+M6+'Billet and Gauge'!D30 -> 50731 | N12: =N5+N6+'Billet and Gauge'!D42 -> 54761 | O12: =O5+O6+'Billet and Gauge'!D30 -> 50731 | P12: =P5+P6+'Billet and Gauge'!D48 -> 61100
B13: 130 mm | C13: Heavy | D13: - | E13: - | F13: =F5+F6+'Billet and Gauge'!D37 -> 47731 | G13: =G5+G6+'Billet and Gauge'!D37 -> 47731 | H13: =H5+H6+'Billet and Gauge'!D42 -> 58000 | I13: =I5+I6+'Billet and Gauge'!D42 -> 56970 | J13: =J5+J6+'Billet and Gauge'!D42 -> 56970 | K13: =K9+K10+'Billet and Gauge'!D46 -> 115000 | L13: =L5+L6+'Billet and Gauge'!D37 -> 51731 | M13: - | N13: =N5+N6+'Billet and Gauge'!D42 -> 54761 | O13: - | P13: =P5+P6+'Billet and Gauge'!D48 -> 61100
B14: 150 mm | C14: Heavy | D14: - | E14: - | F14: =F5+F6+'Billet and Gauge'!D38 -> 49231 | G14: =G5+G6+'Billet and Gauge'!D38 -> 49231 | H14: =H5+H6+'Billet and Gauge'!D43 -> 58500 | I14: =I5+I6+'Billet and Gauge'!D43 -> 57470 | J14: =J5+J6+'Billet and Gauge'!D43 -> 57470 | K14: =K10+K11+'Billet and Gauge'!D47 -> 124000 | L14: =L5+L6+'Billet and Gauge'!D38 -> 53231 | M14: - | N14: =N5+N6+'Billet and Gauge'!D43 -> 55261 | O14: - | P14: =P5+P6+'Billet and Gauge'!D49 -> 64100
B15: 200 mm | C15: Super Heavy | D15: - | E15: - | F15: =F5+F6+'Billet and Gauge'!D39 -> 50731 | G15: =G5+G6+'Billet and Gauge'!D39 -> 50731 | H15: =H5+H6+'Billet and Gauge'!D44 -> 59000 | I15: =I5+I6+'Billet and Gauge'!D44 -> 57970 | J15: =J5+J6+'Billet and Gauge'!D44 -> 57970 | K15: =K11+K12+'Billet and Gauge'!D48 -> 129500 | L15: =L5+L6+'Billet and Gauge'!D39 -> 54731 | M15: - | N15: =N5+N6+'Billet and Gauge'!D44 -> 55761 | O15: - | P15: =P5+P6+'Billet and Gauge'!D50 -> 66100
B16: 250 mm | C16: Ultra Heavy | D16: - | E16: - | F16: - | G16: - | H16: =H5+H6+'Billet and Gauge'!D45 -> 62500 | I16: - | J16: =J5+J6+'Billet and Gauge'!D45 -> 61470 | K16: =K12+K13+'Billet and Gauge'!D49 -> 190000 | L16: - | M16: - | N16: =N5+N6+'Billet and Gauge'!D45 -> 59261 | O16: - | P16: =P5+P6+'Billet and Gauge'!D51 -> 69600
B19: MS Flats | C19: Conversion | D19: ='Billet and Gauge'!C134 -> 500
C20: Base Price: | D20: ='Billet and Gauge'!C9 -> 38511 | E20: ='Billet and Gauge'!C9 -> 38511 | F20: ='Billet and Gauge'!C9 -> 38511 | G20: ='Billet and Gauge'!E9 -> 42511 | H20: ='Billet and Gauge'!J9 -> 46750 | I20: ='Billet and Gauge'!I9 -> 45500 | J20: ='Billet and Gauge'!K9 -> 47250 | M20: RM Category | O20: Light | P20: Medium | Q20: Heavy | R20: Super Heavy | S20: Ultra Heavy
C21: Load+Trspt+Brok | D21: =385+250+85 -> 720 | E21: =385+250+85 -> 720 | F21: =385+250+85 -> 720 | G21: =385+250+85 -> 720 | H21: =385+250+85 -> 720 | I21: 2500 | J21: 1250 | M21: PG /NTPC | N21: MS
C22: Make: | D22: (NPG) | E22: (NPG) | F22: (NPG) | G22: (TESTED) | H22: (PG) | I22: (PG) | J22: (PG) | M22: MAIN /BSEN | N22: MS
B23: Sections | D23: SRS | E23: ANKIT | F23: RATS/MAHS | G23: ANKIT | H23: ANKIT | I23: SWASTIKA | J23: SREL | M23: NPG | N23: MS | O23: =AVERAGE(D9:E11) -> 46231 | P23: =AVERAGE(D12:G12) -> 46481 | Q23: =AVERAGE(F13:G14) -> 48481 | R23: =AVERAGE(F15:G15) -> 50731 | S23: =AVERAGE(H16:J16) -> 61985
B24: 40/50 x 6 | D24: =D19+D20+D21+'Billet and Gauge'!D55 -> 46531 | E24: =D19+E20+E21+'Billet and Gauge'!D55 -> 46531 | F24: =D19+F20+F21+'Billet and Gauge'!D55 -> 46531 | G24: =D19+G20+G21+'Billet and Gauge'!D55 -> 50531 | H24: =D19+H20+H21+'Billet and Gauge'!D55 -> 54770 | I24: =D19+I20+I21+'Billet and Gauge'!D61 -> 58000 | J24: =D19+J20+J21+'Billet and Gauge'!D61 -> 58500 | M24: CORE | N24: MS
B25: 50/65/75/100 x 8/10/12 | D25: =D19+D20+D21+'Billet and Gauge'!D54 -> 46031 | E25: =D19+E20+E21+'Billet and Gauge'!D54 -> 46031 | F25: =D19+F20+F21+'Billet and Gauge'!D54 -> 46031 | G25: =D19+G20+G21+'Billet and Gauge'!D54 -> 50031 | H25: =D19+H20+H21+'Billet and Gauge'!D54 -> 54270 | I25: =D19+I20+I21+'Billet and Gauge'!D61 -> 58000 | J25: =D19+J20+J21+'Billet and Gauge'!D61 -> 58500 | M25: PG /NTPC | N25: HT
B26: 25 x 5/6 | D26: =D19+D20+D21+'Billet and Gauge'!D59 -> 47031 | E26: - | F26: - | G26: - | H26: - | I26: - | J26: - | M26: MAIN /BSEN | N26: HT
B27: 25 x 3/4 | D27: =D19+D20+D21+'Billet and Gauge'!D60 -> 48031 | E27: - | F27: - | G27: - | H27: - | I27: - | J27: - | M27: NPG | N27: HT
B28: 125/150 x 6/8/10/12/16 | D28: =D19+D20+D21+'Billet and Gauge'!D56 -> 46531 | E28: =D19+E20+E21+'Billet and Gauge'!D56 -> 46531 | F28: =D19+F20+F21+'Billet and Gauge'!D56 -> 46531 | G28: =D19+G20+G21+'Billet and Gauge'!D56 -> 50531 | H28: =D19+H20+H21+'Billet and Gauge'!D56 -> 54770 | I28: - | J28: - | M28: CORE | N28: HT
B29: 200 x 6/8/10/12/16 | D29: =D19+D20+D21+'Billet and Gauge'!D57 -> 47531 | E29: =D19+E20+E21+'Billet and Gauge'!D57 -> 47531 | F29: =D19+F20+F21+'Billet and Gauge'!D57 -> 47531 | G29: =D19+G20+G21+'Billet and Gauge'!D57 -> 51531 | H29: =D19+H20+H21+'Billet and Gauge'!D57 -> 55770 | I29: - | J29: -
B30: 250 x 6/8/10/12 | D30: =D19+D20+D21+'Billet and Gauge'!D58 -> 49031 | E30: - | F30: =D19+F20+F21+'Billet and Gauge'!D58 -> 49031 | G30: - | H30: - | I30: - | J30: -
B33: MS Rounds | C33: Conversion | D33: ='Billet and Gauge'!C137 -> 500
C34: Base Price: | D34: ='Billet and Gauge'!C9 -> 38511 | E34: ='Billet and Gauge'!C9 -> 38511 | F34: ='Billet and Gauge'!C9 -> 38511 | G34: ='Billet and Gauge'!E9 -> 42511 | H34: ='Billet and Gauge'!E21 -> 55500 | I34: ='Billet and Gauge'!G21 -> 58500
C35: Load+Trspt+Brok | D35: =385+250+85 -> 720 | E35: =385+250+85 -> 720 | F35: =385+250+85 -> 720 | G35: =385+250+85 -> 720 | H35: 1250 | I35: 3750
C36: Make: | D36: (NPG) | E36: (NPG) | F36: (NPG) | G36: (Tested) | H36: (MAIN) | I36: (MAIN)
B37: Sections | C37: Supplier: | D37: SRS | E37: ANKIT | F37: RATS | G37: SRS | H37: BHAGWATI | I37: BHAGWATI
B38: 28, 30, 32, 36, 40, 42, 45, 50 mm | D38: =D33+D34+D35+'Billet and Gauge'!D65 -> 46031 | E38: =D33+E34+E35+'Billet and Gauge'!D65 -> 46031 | F38: =D33+F34+F35+'Billet and Gauge'!D65 -> 46031 | G38: =D33+G34+G35+'Billet and Gauge'!D65 -> 50031 | H38: =H34+H35 -> 56750 | I38: =I34+I35 -> 62250
B39: 20, 22, 25 mm | D39: =D33+D34+D35+'Billet and Gauge'!D66 -> 46531 | E39: =D33+E34+E35+'Billet and Gauge'!D66 -> 46531 | F39: =D33+F34+F35+'Billet and Gauge'!D66 -> 46531 | G39: =D33+G34+G35+'Billet and Gauge'!D66 -> 50531 | H39: =H34+H35 -> 56750 | I39: =I34+I35 -> 62250
B40: 54, 56, 60, 63, 65 mm | D40: - | E40: - | F40: - | G40: - | H40: =H34+H35 -> 56750 | I40: =I34+I35 -> 62250
B43: RSJ, WPB, Channels & Beams | C43: MS | D43: ='Billet and Gauge'!C140 -> 0
C44: HT | D44: ='Billet and Gauge'!C141 -> 2000
C45: Base Price: | D45: ='Billet and Gauge'!D9 -> 44511 | E45: ='Billet and Gauge'!D9 -> 44511 | F45: ='Billet and Gauge'!F9 -> 48511 | G45: ='Billet and Gauge'!F9 -> 48511 | H45: ='Billet and Gauge'!F9 -> 48511 | I45: ='Billet and Gauge'!L9 -> 45950 | J45: ='Billet and Gauge'!H9 -> 44500 | L45: ='Billet and Gauge'!M9 -> 50000
C46: Load+Trspt+Brok | D46: =385+250+85 -> 720 | E46: =385+250+85 -> 720 | F46: =385+250+85 -> 720 | G46: =385+250+85 -> 720 | H46: =385+250+85 -> 720 | I46: 1250 | J46: 2500 | L46: 1100
C47: Make: | D47: (NPG) | E47: (NPG) | F47: (TESTED) | G47: (CORE) | H47: (CORE) | I47: (MAIN) | J47: (MAIN) | L47: (MAIN)
...
